[2023-06-29 08:32:58,555] {taskinstance.py:1032} INFO - Dependencies all met for <TaskInstance: apartment_transaction_etl_dag.run_etl_task manual__2023-06-29T08:32:56.451099+00:00 [queued]>
[2023-06-29 08:32:58,568] {taskinstance.py:1032} INFO - Dependencies all met for <TaskInstance: apartment_transaction_etl_dag.run_etl_task manual__2023-06-29T08:32:56.451099+00:00 [queued]>
[2023-06-29 08:32:58,568] {taskinstance.py:1238} INFO - 
--------------------------------------------------------------------------------
[2023-06-29 08:32:58,568] {taskinstance.py:1239} INFO - Starting attempt 1 of 1
[2023-06-29 08:32:58,568] {taskinstance.py:1240} INFO - 
--------------------------------------------------------------------------------
[2023-06-29 08:32:58,582] {taskinstance.py:1259} INFO - Executing <Task(PythonOperator): run_etl_task> on 2023-06-29 08:32:56.451099+00:00
[2023-06-29 08:32:58,586] {standard_task_runner.py:52} INFO - Started process 500 to run task
[2023-06-29 08:32:58,590] {standard_task_runner.py:76} INFO - Running: ['***', 'tasks', 'run', 'apartment_transaction_etl_dag', 'run_etl_task', 'manual__2023-06-29T08:32:56.451099+00:00', '--job-id', '25', '--raw', '--subdir', 'DAGS_FOLDER/apartment_transaction_dag.py', '--cfg-path', '/tmp/tmpqjutmd7s', '--error-file', '/tmp/tmp84f_vft1']
[2023-06-29 08:32:58,592] {standard_task_runner.py:77} INFO - Job 25: Subtask run_etl_task
[2023-06-29 08:32:58,656] {logging_mixin.py:109} INFO - Running <TaskInstance: apartment_transaction_etl_dag.run_etl_task manual__2023-06-29T08:32:56.451099+00:00 [running]> on host d3599d0cd7b8
[2023-06-29 08:32:58,723] {taskinstance.py:1426} INFO - Exporting the following env vars:
AIRFLOW_CTX_DAG_OWNER=***
AIRFLOW_CTX_DAG_ID=apartment_transaction_etl_dag
AIRFLOW_CTX_TASK_ID=run_etl_task
AIRFLOW_CTX_EXECUTION_DATE=2023-06-29T08:32:56.451099+00:00
AIRFLOW_CTX_DAG_RUN_ID=manual__2023-06-29T08:32:56.451099+00:00
[2023-06-29 08:32:58,724] {logging_mixin.py:109} INFO - >>> Running 'etl' function. Logged at 2023-06-29 08:32:58.724652+00:00
[2023-06-29 08:32:58,724] {logging_mixin.py:109} INFO - >>> Running 'connect_db' function. Logged at 2023-06-29 08:32:58.724935+00:00
[2023-06-29 08:32:58,725] {logging_mixin.py:109} INFO - Connecting to DB
[2023-06-29 08:32:58,789] {logging_mixin.py:109} INFO - >>> Function: 'connect_db' executed. Logged at 2023-06-29 08:32:58.724935+00:00
[2023-06-29 08:32:58,789] {logging_mixin.py:109} INFO - >>> Running 'extract' function. Logged at 2023-06-29 08:32:58.789347+00:00
[2023-06-29 08:32:58,789] {logging_mixin.py:109} INFO - Reading dataset from https://gist.githubusercontent.com/mmphego/5b6fc4d6dc3c8fba4fce9d994a2fe16b/raw/ab5df0e76812e13df5b31e466a5fb787fac0599a/wine_quality.csv
[2023-06-29 08:32:59,302] {taskinstance.py:1700} ERROR - Task failed with exception
Traceback (most recent call last):
  File "/home/airflow/.local/lib/python3.7/site-packages/airflow/models/taskinstance.py", line 1329, in _run_raw_task
    self._execute_task_with_callbacks(context)
  File "/home/airflow/.local/lib/python3.7/site-packages/airflow/models/taskinstance.py", line 1455, in _execute_task_with_callbacks
    result = self._execute_task(context, self.task)
  File "/home/airflow/.local/lib/python3.7/site-packages/airflow/models/taskinstance.py", line 1511, in _execute_task
    result = execute_callable(context=context)
  File "/home/airflow/.local/lib/python3.7/site-packages/airflow/operators/python.py", line 174, in execute
    return_value = self.execute_callable()
  File "/home/airflow/.local/lib/python3.7/site-packages/airflow/operators/python.py", line 185, in execute_callable
    return self.python_callable(*self.op_args, **self.op_kwargs)
  File "/opt/airflow/dags/apartment_transaction_dag.py", line 46, in wrapper
    to_execute = func(*args, **kwargs)
  File "/opt/airflow/dags/apartment_transaction_dag.py", line 137, in etl
    raw_df = extract(DATASET_URL)
  File "/opt/airflow/dags/apartment_transaction_dag.py", line 46, in wrapper
    to_execute = func(*args, **kwargs)
  File "/opt/airflow/dags/apartment_transaction_dag.py", line 83, in extract
    year = execution_date.year
NameError: name 'execution_date' is not defined
[2023-06-29 08:32:59,320] {taskinstance.py:1277} INFO - Marking task as FAILED. dag_id=apartment_transaction_etl_dag, task_id=run_etl_task, execution_date=20230629T083256, start_date=20230629T083258, end_date=20230629T083259
[2023-06-29 08:32:59,336] {standard_task_runner.py:92} ERROR - Failed to execute job 25 for task run_etl_task
Traceback (most recent call last):
  File "/home/airflow/.local/lib/python3.7/site-packages/airflow/task/task_runner/standard_task_runner.py", line 85, in _start_by_fork
    args.func(args, dag=self.dag)
  File "/home/airflow/.local/lib/python3.7/site-packages/airflow/cli/cli_parser.py", line 48, in command
    return func(*args, **kwargs)
  File "/home/airflow/.local/lib/python3.7/site-packages/airflow/utils/cli.py", line 92, in wrapper
    return f(*args, **kwargs)
  File "/home/airflow/.local/lib/python3.7/site-packages/airflow/cli/commands/task_command.py", line 298, in task_run
    _run_task_by_selected_method(args, dag, ti)
  File "/home/airflow/.local/lib/python3.7/site-packages/airflow/cli/commands/task_command.py", line 107, in _run_task_by_selected_method
    _run_raw_task(args, ti)
  File "/home/airflow/.local/lib/python3.7/site-packages/airflow/cli/commands/task_command.py", line 184, in _run_raw_task
    error_file=args.error_file,
  File "/home/airflow/.local/lib/python3.7/site-packages/airflow/utils/session.py", line 70, in wrapper
    return func(*args, session=session, **kwargs)
  File "/home/airflow/.local/lib/python3.7/site-packages/airflow/models/taskinstance.py", line 1329, in _run_raw_task
    self._execute_task_with_callbacks(context)
  File "/home/airflow/.local/lib/python3.7/site-packages/airflow/models/taskinstance.py", line 1455, in _execute_task_with_callbacks
    result = self._execute_task(context, self.task)
  File "/home/airflow/.local/lib/python3.7/site-packages/airflow/models/taskinstance.py", line 1511, in _execute_task
    result = execute_callable(context=context)
  File "/home/airflow/.local/lib/python3.7/site-packages/airflow/operators/python.py", line 174, in execute
    return_value = self.execute_callable()
  File "/home/airflow/.local/lib/python3.7/site-packages/airflow/operators/python.py", line 185, in execute_callable
    return self.python_callable(*self.op_args, **self.op_kwargs)
  File "/opt/airflow/dags/apartment_transaction_dag.py", line 46, in wrapper
    to_execute = func(*args, **kwargs)
  File "/opt/airflow/dags/apartment_transaction_dag.py", line 137, in etl
    raw_df = extract(DATASET_URL)
  File "/opt/airflow/dags/apartment_transaction_dag.py", line 46, in wrapper
    to_execute = func(*args, **kwargs)
  File "/opt/airflow/dags/apartment_transaction_dag.py", line 83, in extract
    year = execution_date.year
NameError: name 'execution_date' is not defined
[2023-06-29 08:32:59,372] {local_task_job.py:154} INFO - Task exited with return code 1
[2023-06-29 08:32:59,411] {local_task_job.py:264} INFO - 0 downstream tasks scheduled from follow-on schedule check
